2024-09-11 09:12:08,215 - WARNING -  * Debugger is active!
2024-09-11 09:12:08,217 - INFO -  * Debugger PIN: 106-758-978
2024-09-11 09:15:29,033 - INFO - 172.21.0.1 - - [11/Sep/2024 09:15:29] "GET /login HTTP/1.1" 200 -
2024-09-11 09:15:29,089 - INFO - 172.21.0.1 - - [11/Sep/2024 09:15:29] "[36mGET /static/images/logo_LUFTH_TRACK_DATA_250x250.png HTTP/1.1[0m" 304 -
2024-09-11 09:15:35,863 - INFO - 172.21.0.1 - - [11/Sep/2024 09:15:35] "[32mPOST /login HTTP/1.1[0m" 302 -
2024-09-11 09:15:35,872 - ERROR - Exception possibly due to cache backend.
Traceback (most recent call last):
  File "/usr/local/lib/python3.9/site-packages/flask_caching/__init__.py", line 392, in decorated_function
    rv = self.cache.get(cache_key)
  File "/usr/local/lib/python3.9/site-packages/flask_caching/__init__.py", line 191, in cache
    return app.extensions["cache"][self]
KeyError: <flask_caching.Cache object at 0x7f48b1dd13a0>
2024-09-11 09:15:36,236 - ERROR - Exception possibly due to cache backend.
Traceback (most recent call last):
  File "/usr/local/lib/python3.9/site-packages/flask_caching/__init__.py", line 392, in decorated_function
    rv = self.cache.get(cache_key)
  File "/usr/local/lib/python3.9/site-packages/flask_caching/__init__.py", line 191, in cache
    return app.extensions["cache"][self]
KeyError: <flask_caching.Cache object at 0x7f48b1dd13a0>
2024-09-11 09:15:36,942 - INFO - 172.21.0.1 - - [11/Sep/2024 09:15:36] "GET /index HTTP/1.1" 200 -
2024-09-11 09:15:37,009 - INFO - 172.21.0.1 - - [11/Sep/2024 09:15:37] "[36mGET /static/images/logo_LUFTH_TRACK_DATA_250x250.png HTTP/1.1[0m" 304 -
2024-09-11 09:15:37,016 - INFO - 172.21.0.1 - - [11/Sep/2024 09:15:37] "[36mGET /static/css/styles.css HTTP/1.1[0m" 304 -
2024-09-11 09:16:52,866 - ERROR - Exception possibly due to cache backend.
Traceback (most recent call last):
  File "/usr/local/lib/python3.9/site-packages/flask_caching/__init__.py", line 392, in decorated_function
    rv = self.cache.get(cache_key)
  File "/usr/local/lib/python3.9/site-packages/flask_caching/__init__.py", line 191, in cache
    return app.extensions["cache"][self]
KeyError: <flask_caching.Cache object at 0x7f48b1dd13a0>
2024-09-11 09:16:52,882 - ERROR - Exception possibly due to cache backend.
Traceback (most recent call last):
  File "/usr/local/lib/python3.9/site-packages/flask_caching/__init__.py", line 392, in decorated_function
    rv = self.cache.get(cache_key)
  File "/usr/local/lib/python3.9/site-packages/flask_caching/__init__.py", line 191, in cache
    return app.extensions["cache"][self]
KeyError: <flask_caching.Cache object at 0x7f48b1dd13a0>
2024-09-11 09:16:52,897 - ERROR - Exception possibly due to cache backend.
Traceback (most recent call last):
  File "/usr/local/lib/python3.9/site-packages/flask_caching/__init__.py", line 392, in decorated_function
    rv = self.cache.get(cache_key)
  File "/usr/local/lib/python3.9/site-packages/flask_caching/__init__.py", line 191, in cache
    return app.extensions["cache"][self]
KeyError: <flask_caching.Cache object at 0x7f48b1dd13a0>
2024-09-11 09:16:53,004 - INFO - 172.21.0.1 - - [11/Sep/2024 09:16:53] "GET /airport HTTP/1.1" 200 -
2024-09-11 09:16:53,070 - INFO - 172.21.0.1 - - [11/Sep/2024 09:16:53] "[36mGET /static/css/styles.css HTTP/1.1[0m" 304 -
2024-09-11 09:16:53,078 - INFO - 172.21.0.1 - - [11/Sep/2024 09:16:53] "[36mGET /static/images/logo_LUFTH_TRACK_DATA_250x250.png HTTP/1.1[0m" 304 -
2024-09-11 09:17:25,701 - ERROR - Exception possibly due to cache backend.
Traceback (most recent call last):
  File "/usr/local/lib/python3.9/site-packages/flask_caching/__init__.py", line 392, in decorated_function
    rv = self.cache.get(cache_key)
  File "/usr/local/lib/python3.9/site-packages/flask_caching/__init__.py", line 191, in cache
    return app.extensions["cache"][self]
KeyError: <flask_caching.Cache object at 0x7f48b1dd13a0>
2024-09-11 09:17:25,712 - ERROR - Exception possibly due to cache backend.
Traceback (most recent call last):
  File "/usr/local/lib/python3.9/site-packages/flask_caching/__init__.py", line 392, in decorated_function
    rv = self.cache.get(cache_key)
  File "/usr/local/lib/python3.9/site-packages/flask_caching/__init__.py", line 191, in cache
    return app.extensions["cache"][self]
KeyError: <flask_caching.Cache object at 0x7f48b1dd13a0>
2024-09-11 09:17:25,732 - ERROR - Exception possibly due to cache backend.
Traceback (most recent call last):
  File "/usr/local/lib/python3.9/site-packages/flask_caching/__init__.py", line 392, in decorated_function
    rv = self.cache.get(cache_key)
  File "/usr/local/lib/python3.9/site-packages/flask_caching/__init__.py", line 191, in cache
    return app.extensions["cache"][self]
KeyError: <flask_caching.Cache object at 0x7f48b1dd13a0>
2024-09-11 09:17:25,866 - INFO - 172.21.0.1 - - [11/Sep/2024 09:17:25] "POST /airport HTTP/1.1" 200 -
2024-09-11 09:18:19,979 - ERROR - Exception possibly due to cache backend.
Traceback (most recent call last):
  File "/usr/local/lib/python3.9/site-packages/flask_caching/__init__.py", line 392, in decorated_function
    rv = self.cache.get(cache_key)
  File "/usr/local/lib/python3.9/site-packages/flask_caching/__init__.py", line 191, in cache
    return app.extensions["cache"][self]
KeyError: <flask_caching.Cache object at 0x7f48b1dd13a0>
2024-09-11 09:18:20,007 - ERROR - Exception possibly due to cache backend.
Traceback (most recent call last):
  File "/usr/local/lib/python3.9/site-packages/flask_caching/__init__.py", line 392, in decorated_function
    rv = self.cache.get(cache_key)
  File "/usr/local/lib/python3.9/site-packages/flask_caching/__init__.py", line 191, in cache
    return app.extensions["cache"][self]
KeyError: <flask_caching.Cache object at 0x7f48b1dd13a0>
2024-09-11 09:18:20,066 - ERROR - Exception possibly due to cache backend.
Traceback (most recent call last):
  File "/usr/local/lib/python3.9/site-packages/flask_caching/__init__.py", line 392, in decorated_function
    rv = self.cache.get(cache_key)
  File "/usr/local/lib/python3.9/site-packages/flask_caching/__init__.py", line 191, in cache
    return app.extensions["cache"][self]
KeyError: <flask_caching.Cache object at 0x7f48b1dd13a0>
2024-09-11 09:18:20,091 - ERROR - Exception possibly due to cache backend.
Traceback (most recent call last):
  File "/usr/local/lib/python3.9/site-packages/flask_caching/__init__.py", line 392, in decorated_function
    rv = self.cache.get(cache_key)
  File "/usr/local/lib/python3.9/site-packages/flask_caching/__init__.py", line 191, in cache
    return app.extensions["cache"][self]
KeyError: <flask_caching.Cache object at 0x7f48b1dd13a0>
2024-09-11 09:18:20,125 - ERROR - Exception possibly due to cache backend.
Traceback (most recent call last):
  File "/usr/local/lib/python3.9/site-packages/flask_caching/__init__.py", line 392, in decorated_function
    rv = self.cache.get(cache_key)
  File "/usr/local/lib/python3.9/site-packages/flask_caching/__init__.py", line 191, in cache
    return app.extensions["cache"][self]
KeyError: <flask_caching.Cache object at 0x7f48b1dd13a0>
2024-09-11 09:18:20,277 - ERROR - Exception possibly due to cache backend.
Traceback (most recent call last):
  File "/usr/local/lib/python3.9/site-packages/flask_caching/__init__.py", line 392, in decorated_function
    rv = self.cache.get(cache_key)
  File "/usr/local/lib/python3.9/site-packages/flask_caching/__init__.py", line 191, in cache
    return app.extensions["cache"][self]
KeyError: <flask_caching.Cache object at 0x7f48b1dd13a0>
2024-09-11 09:18:20,312 - ERROR - Exception possibly due to cache backend.
Traceback (most recent call last):
  File "/usr/local/lib/python3.9/site-packages/flask_caching/__init__.py", line 392, in decorated_function
    rv = self.cache.get(cache_key)
  File "/usr/local/lib/python3.9/site-packages/flask_caching/__init__.py", line 191, in cache
    return app.extensions["cache"][self]
KeyError: <flask_caching.Cache object at 0x7f48b1dd13a0>
2024-09-11 09:18:20,333 - ERROR - Exception possibly due to cache backend.
Traceback (most recent call last):
  File "/usr/local/lib/python3.9/site-packages/flask_caching/__init__.py", line 392, in decorated_function
    rv = self.cache.get(cache_key)
  File "/usr/local/lib/python3.9/site-packages/flask_caching/__init__.py", line 191, in cache
    return app.extensions["cache"][self]
KeyError: <flask_caching.Cache object at 0x7f48b1dd13a0>
2024-09-11 09:18:20,356 - ERROR - Exception possibly due to cache backend.
Traceback (most recent call last):
  File "/usr/local/lib/python3.9/site-packages/flask_caching/__init__.py", line 392, in decorated_function
    rv = self.cache.get(cache_key)
  File "/usr/local/lib/python3.9/site-packages/flask_caching/__init__.py", line 191, in cache
    return app.extensions["cache"][self]
KeyError: <flask_caching.Cache object at 0x7f48b1dd13a0>
2024-09-11 09:18:20,401 - INFO - 172.21.0.1 - - [11/Sep/2024 09:18:20] "GET /statistics HTTP/1.1" 200 -
2024-09-11 09:18:20,442 - INFO - 172.21.0.1 - - [11/Sep/2024 09:18:20] "[36mGET /static/css/styles.css HTTP/1.1[0m" 304 -
2024-09-11 09:18:20,447 - INFO - 172.21.0.1 - - [11/Sep/2024 09:18:20] "[36mGET /static/images/logo_LUFTH_TRACK_DATA_250x250.png HTTP/1.1[0m" 304 -
